<?xml version="1.0"?>
<robot name="wild_thumper" xmlns:xacro="http://ros.org/wiki/xacro">
	<xacro:property name="PI" value="3.1415926535897931" />
        <material name="Black">
            <color rgba="${45/255} ${45/255} ${45/255} 1.0"/>
        </material>
	    
        <link name="base_footprint">
            <visual>
                <geometry>
                    <box size="0.28 0.31 0.000001"/>
                </geometry> 
            </visual>    
        </link>
	<link name="base_link">
		<collision>
			<geometry>
				<box size="0.23 0.12 0.09"/>
			</geometry>
		</collision>
		<visual>
                        <material name="Black"/> 
                        <origin xyz="-0.00275 0 0.0" rpy="0 0 0"/>  
			<geometry>
				<mesh filename="package://wild_thumper/include/meshes/wild_thumper_4wd.stl" /> 
			</geometry>
		</visual>
       </link>

        <link name="mount_spacers">
		<visual>
                        <material name="Black"/> 
                        <origin xyz="0 0 0" rpy="0 0 0"/>  
			<geometry>
				<box size="0.24 0.12 0.03"/>
			</geometry>
		</visual>
	</link>
   
    <link name="mount_lidar">
		<visual>
                        <material name="Black"/> 
                        <origin xyz="0 0 0" rpy="0 0 0"/>  
			<geometry>
				<box size="0.09 0.087 0.002"/>
			</geometry>
		</visual>
	</link>
      
    <link name="laser">
		<visual>
                        <material name="Black"/> 
                        <axis xyz="1 0 0" rpy="0 0 0"/>   
                        <origin xyz="-0.032 0.035 -0.045" rpy="${PI/2} 0 0"/>  
               		<geometry>
				<mesh filename="package://wild_thumper/include/meshes/rplidar.stl" scale="0.001 0.001 0.001"/> 
			</geometry>
		</visual>
	</link>

	<link name="base_imu_link">
		<visual>
                <geometry>
                    <box size="0.02 0.02 0.02"/>
                </geometry> 
            </visual> 
	</link>
 
    <joint name="base_link_joint" type="fixed">
        <origin rpy="0 0 0" xyz="0 0 -0.082 "/>
        <child link="base_footprint"/>
        <parent link="base_link"/>
    </joint> 

    <joint name="mount_spacer_joint" type="fixed">
		<parent link="base_link"/>
		<child link="mount_spacers"/>
		<origin xyz="0.00 0.0 0.06" rpy="0 0 0"/>
	</joint>

    <joint name="mount_lidar" type="fixed">
		<parent link="base_link"/>
		<child link="mount_lidar"/>
		<origin xyz="-0.07 0 0.086" rpy="0 0 0"/>
	</joint>

    <joint name="laser" type="fixed">
		<parent link="base_link"/>
		<child link="laser"/>
        <origin xyz="-0.08 0 0.150" rpy="0 0 0"/>  
	</joint>

    <joint name="base_imu" type="fixed">
		<parent link="base_link"/>
		<child link="base_imu_link"/>
        <origin xyz="0.00 0 0.10" rpy="0 0 0"/>  
	</joint>

        <xacro:macro name="wheel" params="pos side xyz rpy">   
		<link name="${pos}_${side}_wheel">
			<visual>
                                <material name="Black"/>   
				<origin xyz="0 0 0" rpy="0 0 0"/>
				<geometry>
					<mesh filename="package://wild_thumper/include/meshes/wheel_${side}.stl" />
				</geometry>
			</visual>
			<collision>
				<origin xyz="0 0 0" rpy="${PI/2} 0 0"/>
				<geometry>
					<cylinder radius="0.06" length="0.06"/>
				</geometry>
			</collision>
			<inertial>
				<origin xyz="0 0 0" rpy="0 0 0"/>
				<mass value="0.2"/>
				<inertia ixx="0.00024" ixy="0" ixz="0" iyy="0.00036" iyz="0" izz="0.00024"/>
			</inertial>
		</link>


		<joint name="${pos}_${side}_wheel_joint" type="continuous">
                        <axis xyz="0 1 0" rpy="0 0 0"/>  
			<parent link="base_link"/>
			<child link="${pos}_${side}_wheel"/>
			<origin xyz="${xyz}" rpy="${rpy}"/>
		</joint>

	</xacro:macro>

        <xacro:macro name="spacer" params="sensor num len rad xyz">
             <link name="${sensor}_${num}_spacer">
                <visual>
                    <geometry>
                        <cylinder length="${len}" radius="${rad}"/>
                    </geometry>
                </visual>
            </link>
            <joint name="${sensor}_${num}_spacer_joint" type="continuous">
		<parent link="mount_spacers"/>
		<child link="${sensor}_${num}_spacer"/>
		<origin xyz="${xyz}" rpy="0 0 0"/>
            </joint>
        </xacro:macro>  

        <xacro:wheel pos="rear" side="left"   xyz="-0.07525  0.12 -0.025" rpy="0 0 0" />
	<xacro:wheel pos="rear" side="right"  xyz="-0.07525 -0.12 -0.025" rpy="0 0 0" />
	<xacro:wheel pos="front" side="left"  xyz=" 0.07525  0.12 -0.025" rpy="0 0 0" />
	<xacro:wheel pos="front" side="right" xyz=" 0.07525 -0.12 -0.025" rpy="0 0 0" />

        <xacro:spacer sensor="lidar" num="1_1" len="0.01" rad="0.0025" xyz="-0.03 -0.04 0.020" />  
        <xacro:spacer sensor="lidar" num="1_2" len="0.01" rad="0.0025" xyz="-0.03  0.04 0.020" />
        <xacro:spacer sensor="lidar" num="1_3" len="0.01" rad="0.0025" xyz="-0.11 -0.04 0.020" />  
        <xacro:spacer sensor="lidar" num="1_4" len="0.01" rad="0.0025" xyz="-0.11  0.04 0.020" />  

        <xacro:spacer sensor="lidar" num="2_1" len="0.02" rad="0.0028" xyz="-0.035 -0.02 0.035" />  
        <xacro:spacer sensor="lidar" num="2_2" len="0.02" rad="0.0028" xyz="-0.035  0.02 0.035" />
        <xacro:spacer sensor="lidar" num="2_3" len="0.02" rad="0.0028" xyz="-0.105 -0.028 0.035" />  
        <xacro:spacer sensor="lidar" num="2_4" len="0.02" rad="0.0028" xyz="-0.105  0.028 0.035" />  


</robot>
